{
 "cells": [
  {
   "cell_type": "code",
   "execution_count": 1,
   "metadata": {},
   "outputs": [],
   "source": [
    "import gdown"
   ]
  },
  {
   "cell_type": "code",
   "execution_count": 2,
   "metadata": {},
   "outputs": [],
   "source": [
    "import os"
   ]
  },
  {
   "cell_type": "code",
   "execution_count": 3,
   "metadata": {},
   "outputs": [],
   "source": [
    "os.chdir('../')"
   ]
  },
  {
   "cell_type": "code",
   "execution_count": 4,
   "metadata": {},
   "outputs": [
    {
     "data": {
      "text/plain": [
       "'c:\\\\object detection\\\\End-to-end-waste-detection-using-Yolov5'"
      ]
     },
     "execution_count": 4,
     "metadata": {},
     "output_type": "execute_result"
    }
   ],
   "source": [
    "%pwd"
   ]
  },
  {
   "cell_type": "code",
   "execution_count": 5,
   "metadata": {},
   "outputs": [],
   "source": [
    "url = \"https://drive.google.com/file/d/1MMMuun4ioLc046yeqWUuGnTQOSwe_VVK/view?usp=sharing\""
   ]
  },
  {
   "cell_type": "code",
   "execution_count": 6,
   "metadata": {},
   "outputs": [
    {
     "data": {
      "text/plain": [
       "'1MMMuun4ioLc046yeqWUuGnTQOSwe_VVK'"
      ]
     },
     "execution_count": 6,
     "metadata": {},
     "output_type": "execute_result"
    }
   ],
   "source": [
    "file_id = url.split(\"/\")[-2]\n",
    "file_id"
   ]
  },
  {
   "cell_type": "code",
   "execution_count": 14,
   "metadata": {},
   "outputs": [],
   "source": [
    "output_path = \"data/waste_data.zip\"\n",
    "file_id = \"1MMMuun4ioLc046yeqWUuGnTQOSwe_VVK\"  # Ensure this is correct\n",
    "url = f\"https://drive.google.com/uc?id={file_id}\""
   ]
  },
  {
   "cell_type": "code",
   "execution_count": 17,
   "metadata": {},
   "outputs": [
    {
     "ename": "ConnectionError",
     "evalue": "HTTPSConnectionPool(host='drive.google.com', port=443): Max retries exceeded with url: /uc?id=1MMMuun4ioLc046yeqWUuGnTQOSwe_VVK (Caused by NameResolutionError(\"<urllib3.connection.HTTPSConnection object at 0x000001B67501F670>: Failed to resolve 'drive.google.com' ([Errno 11001] getaddrinfo failed)\"))",
     "output_type": "error",
     "traceback": [
      "\u001b[1;31m---------------------------------------------------------------------------\u001b[0m",
      "\u001b[1;31mgaierror\u001b[0m                                  Traceback (most recent call last)",
      "File \u001b[1;32mc:\\anaconda\\envs\\object\\lib\\site-packages\\urllib3\\connection.py:198\u001b[0m, in \u001b[0;36mHTTPConnection._new_conn\u001b[1;34m(self)\u001b[0m\n\u001b[0;32m    197\u001b[0m \u001b[38;5;28;01mtry\u001b[39;00m:\n\u001b[1;32m--> 198\u001b[0m     sock \u001b[38;5;241m=\u001b[39m \u001b[43mconnection\u001b[49m\u001b[38;5;241;43m.\u001b[39;49m\u001b[43mcreate_connection\u001b[49m\u001b[43m(\u001b[49m\n\u001b[0;32m    199\u001b[0m \u001b[43m        \u001b[49m\u001b[43m(\u001b[49m\u001b[38;5;28;43mself\u001b[39;49m\u001b[38;5;241;43m.\u001b[39;49m\u001b[43m_dns_host\u001b[49m\u001b[43m,\u001b[49m\u001b[43m \u001b[49m\u001b[38;5;28;43mself\u001b[39;49m\u001b[38;5;241;43m.\u001b[39;49m\u001b[43mport\u001b[49m\u001b[43m)\u001b[49m\u001b[43m,\u001b[49m\n\u001b[0;32m    200\u001b[0m \u001b[43m        \u001b[49m\u001b[38;5;28;43mself\u001b[39;49m\u001b[38;5;241;43m.\u001b[39;49m\u001b[43mtimeout\u001b[49m\u001b[43m,\u001b[49m\n\u001b[0;32m    201\u001b[0m \u001b[43m        \u001b[49m\u001b[43msource_address\u001b[49m\u001b[38;5;241;43m=\u001b[39;49m\u001b[38;5;28;43mself\u001b[39;49m\u001b[38;5;241;43m.\u001b[39;49m\u001b[43msource_address\u001b[49m\u001b[43m,\u001b[49m\n\u001b[0;32m    202\u001b[0m \u001b[43m        \u001b[49m\u001b[43msocket_options\u001b[49m\u001b[38;5;241;43m=\u001b[39;49m\u001b[38;5;28;43mself\u001b[39;49m\u001b[38;5;241;43m.\u001b[39;49m\u001b[43msocket_options\u001b[49m\u001b[43m,\u001b[49m\n\u001b[0;32m    203\u001b[0m \u001b[43m    \u001b[49m\u001b[43m)\u001b[49m\n\u001b[0;32m    204\u001b[0m \u001b[38;5;28;01mexcept\u001b[39;00m socket\u001b[38;5;241m.\u001b[39mgaierror \u001b[38;5;28;01mas\u001b[39;00m e:\n",
      "File \u001b[1;32mc:\\anaconda\\envs\\object\\lib\\site-packages\\urllib3\\util\\connection.py:60\u001b[0m, in \u001b[0;36mcreate_connection\u001b[1;34m(address, timeout, source_address, socket_options)\u001b[0m\n\u001b[0;32m     58\u001b[0m     \u001b[38;5;28;01mraise\u001b[39;00m LocationParseError(\u001b[38;5;124mf\u001b[39m\u001b[38;5;124m\"\u001b[39m\u001b[38;5;124m'\u001b[39m\u001b[38;5;132;01m{\u001b[39;00mhost\u001b[38;5;132;01m}\u001b[39;00m\u001b[38;5;124m'\u001b[39m\u001b[38;5;124m, label empty or too long\u001b[39m\u001b[38;5;124m\"\u001b[39m) \u001b[38;5;28;01mfrom\u001b[39;00m\u001b[38;5;250m \u001b[39m\u001b[38;5;28;01mNone\u001b[39;00m\n\u001b[1;32m---> 60\u001b[0m \u001b[38;5;28;01mfor\u001b[39;00m res \u001b[38;5;129;01min\u001b[39;00m \u001b[43msocket\u001b[49m\u001b[38;5;241;43m.\u001b[39;49m\u001b[43mgetaddrinfo\u001b[49m\u001b[43m(\u001b[49m\u001b[43mhost\u001b[49m\u001b[43m,\u001b[49m\u001b[43m \u001b[49m\u001b[43mport\u001b[49m\u001b[43m,\u001b[49m\u001b[43m \u001b[49m\u001b[43mfamily\u001b[49m\u001b[43m,\u001b[49m\u001b[43m \u001b[49m\u001b[43msocket\u001b[49m\u001b[38;5;241;43m.\u001b[39;49m\u001b[43mSOCK_STREAM\u001b[49m\u001b[43m)\u001b[49m:\n\u001b[0;32m     61\u001b[0m     af, socktype, proto, canonname, sa \u001b[38;5;241m=\u001b[39m res\n",
      "File \u001b[1;32mc:\\anaconda\\envs\\object\\lib\\socket.py:966\u001b[0m, in \u001b[0;36mgetaddrinfo\u001b[1;34m(host, port, family, type, proto, flags)\u001b[0m\n\u001b[0;32m    965\u001b[0m addrlist \u001b[38;5;241m=\u001b[39m []\n\u001b[1;32m--> 966\u001b[0m \u001b[38;5;28;01mfor\u001b[39;00m res \u001b[38;5;129;01min\u001b[39;00m \u001b[43m_socket\u001b[49m\u001b[38;5;241;43m.\u001b[39;49m\u001b[43mgetaddrinfo\u001b[49m\u001b[43m(\u001b[49m\u001b[43mhost\u001b[49m\u001b[43m,\u001b[49m\u001b[43m \u001b[49m\u001b[43mport\u001b[49m\u001b[43m,\u001b[49m\u001b[43m \u001b[49m\u001b[43mfamily\u001b[49m\u001b[43m,\u001b[49m\u001b[43m \u001b[49m\u001b[38;5;28;43mtype\u001b[39;49m\u001b[43m,\u001b[49m\u001b[43m \u001b[49m\u001b[43mproto\u001b[49m\u001b[43m,\u001b[49m\u001b[43m \u001b[49m\u001b[43mflags\u001b[49m\u001b[43m)\u001b[49m:\n\u001b[0;32m    967\u001b[0m     af, socktype, proto, canonname, sa \u001b[38;5;241m=\u001b[39m res\n",
      "\u001b[1;31mgaierror\u001b[0m: [Errno 11001] getaddrinfo failed",
      "\nThe above exception was the direct cause of the following exception:\n",
      "\u001b[1;31mNameResolutionError\u001b[0m                       Traceback (most recent call last)",
      "File \u001b[1;32mc:\\anaconda\\envs\\object\\lib\\site-packages\\urllib3\\connectionpool.py:787\u001b[0m, in \u001b[0;36mHTTPConnectionPool.urlopen\u001b[1;34m(self, method, url, body, headers, retries, redirect, assert_same_host, timeout, pool_timeout, release_conn, chunked, body_pos, preload_content, decode_content, **response_kw)\u001b[0m\n\u001b[0;32m    786\u001b[0m \u001b[38;5;66;03m# Make the request on the HTTPConnection object\u001b[39;00m\n\u001b[1;32m--> 787\u001b[0m response \u001b[38;5;241m=\u001b[39m \u001b[38;5;28mself\u001b[39m\u001b[38;5;241m.\u001b[39m_make_request(\n\u001b[0;32m    788\u001b[0m     conn,\n\u001b[0;32m    789\u001b[0m     method,\n\u001b[0;32m    790\u001b[0m     url,\n\u001b[0;32m    791\u001b[0m     timeout\u001b[38;5;241m=\u001b[39mtimeout_obj,\n\u001b[0;32m    792\u001b[0m     body\u001b[38;5;241m=\u001b[39mbody,\n\u001b[0;32m    793\u001b[0m     headers\u001b[38;5;241m=\u001b[39mheaders,\n\u001b[0;32m    794\u001b[0m     chunked\u001b[38;5;241m=\u001b[39mchunked,\n\u001b[0;32m    795\u001b[0m     retries\u001b[38;5;241m=\u001b[39mretries,\n\u001b[0;32m    796\u001b[0m     response_conn\u001b[38;5;241m=\u001b[39mresponse_conn,\n\u001b[0;32m    797\u001b[0m     preload_content\u001b[38;5;241m=\u001b[39mpreload_content,\n\u001b[0;32m    798\u001b[0m     decode_content\u001b[38;5;241m=\u001b[39mdecode_content,\n\u001b[0;32m    799\u001b[0m     \u001b[38;5;241m*\u001b[39m\u001b[38;5;241m*\u001b[39mresponse_kw,\n\u001b[0;32m    800\u001b[0m )\n\u001b[0;32m    802\u001b[0m \u001b[38;5;66;03m# Everything went great!\u001b[39;00m\n",
      "File \u001b[1;32mc:\\anaconda\\envs\\object\\lib\\site-packages\\urllib3\\connectionpool.py:488\u001b[0m, in \u001b[0;36mHTTPConnectionPool._make_request\u001b[1;34m(self, conn, method, url, body, headers, retries, timeout, chunked, response_conn, preload_content, decode_content, enforce_content_length)\u001b[0m\n\u001b[0;32m    487\u001b[0m         new_e \u001b[38;5;241m=\u001b[39m _wrap_proxy_error(new_e, conn\u001b[38;5;241m.\u001b[39mproxy\u001b[38;5;241m.\u001b[39mscheme)\n\u001b[1;32m--> 488\u001b[0m     \u001b[38;5;28;01mraise\u001b[39;00m new_e\n\u001b[0;32m    490\u001b[0m \u001b[38;5;66;03m# conn.request() calls http.client.*.request, not the method in\u001b[39;00m\n\u001b[0;32m    491\u001b[0m \u001b[38;5;66;03m# urllib3.request. It also calls makefile (recv) on the socket.\u001b[39;00m\n",
      "File \u001b[1;32mc:\\anaconda\\envs\\object\\lib\\site-packages\\urllib3\\connectionpool.py:464\u001b[0m, in \u001b[0;36mHTTPConnectionPool._make_request\u001b[1;34m(self, conn, method, url, body, headers, retries, timeout, chunked, response_conn, preload_content, decode_content, enforce_content_length)\u001b[0m\n\u001b[0;32m    463\u001b[0m \u001b[38;5;28;01mtry\u001b[39;00m:\n\u001b[1;32m--> 464\u001b[0m     \u001b[38;5;28;43mself\u001b[39;49m\u001b[38;5;241;43m.\u001b[39;49m\u001b[43m_validate_conn\u001b[49m\u001b[43m(\u001b[49m\u001b[43mconn\u001b[49m\u001b[43m)\u001b[49m\n\u001b[0;32m    465\u001b[0m \u001b[38;5;28;01mexcept\u001b[39;00m (SocketTimeout, BaseSSLError) \u001b[38;5;28;01mas\u001b[39;00m e:\n",
      "File \u001b[1;32mc:\\anaconda\\envs\\object\\lib\\site-packages\\urllib3\\connectionpool.py:1093\u001b[0m, in \u001b[0;36mHTTPSConnectionPool._validate_conn\u001b[1;34m(self, conn)\u001b[0m\n\u001b[0;32m   1092\u001b[0m \u001b[38;5;28;01mif\u001b[39;00m conn\u001b[38;5;241m.\u001b[39mis_closed:\n\u001b[1;32m-> 1093\u001b[0m     \u001b[43mconn\u001b[49m\u001b[38;5;241;43m.\u001b[39;49m\u001b[43mconnect\u001b[49m\u001b[43m(\u001b[49m\u001b[43m)\u001b[49m\n\u001b[0;32m   1095\u001b[0m \u001b[38;5;66;03m# TODO revise this, see https://github.com/urllib3/urllib3/issues/2791\u001b[39;00m\n",
      "File \u001b[1;32mc:\\anaconda\\envs\\object\\lib\\site-packages\\urllib3\\connection.py:704\u001b[0m, in \u001b[0;36mHTTPSConnection.connect\u001b[1;34m(self)\u001b[0m\n\u001b[0;32m    703\u001b[0m sock: socket\u001b[38;5;241m.\u001b[39msocket \u001b[38;5;241m|\u001b[39m ssl\u001b[38;5;241m.\u001b[39mSSLSocket\n\u001b[1;32m--> 704\u001b[0m \u001b[38;5;28mself\u001b[39m\u001b[38;5;241m.\u001b[39msock \u001b[38;5;241m=\u001b[39m sock \u001b[38;5;241m=\u001b[39m \u001b[38;5;28;43mself\u001b[39;49m\u001b[38;5;241;43m.\u001b[39;49m\u001b[43m_new_conn\u001b[49m\u001b[43m(\u001b[49m\u001b[43m)\u001b[49m\n\u001b[0;32m    705\u001b[0m server_hostname: \u001b[38;5;28mstr\u001b[39m \u001b[38;5;241m=\u001b[39m \u001b[38;5;28mself\u001b[39m\u001b[38;5;241m.\u001b[39mhost\n",
      "File \u001b[1;32mc:\\anaconda\\envs\\object\\lib\\site-packages\\urllib3\\connection.py:205\u001b[0m, in \u001b[0;36mHTTPConnection._new_conn\u001b[1;34m(self)\u001b[0m\n\u001b[0;32m    204\u001b[0m \u001b[38;5;28;01mexcept\u001b[39;00m socket\u001b[38;5;241m.\u001b[39mgaierror \u001b[38;5;28;01mas\u001b[39;00m e:\n\u001b[1;32m--> 205\u001b[0m     \u001b[38;5;28;01mraise\u001b[39;00m NameResolutionError(\u001b[38;5;28mself\u001b[39m\u001b[38;5;241m.\u001b[39mhost, \u001b[38;5;28mself\u001b[39m, e) \u001b[38;5;28;01mfrom\u001b[39;00m\u001b[38;5;250m \u001b[39m\u001b[38;5;21;01me\u001b[39;00m\n\u001b[0;32m    206\u001b[0m \u001b[38;5;28;01mexcept\u001b[39;00m SocketTimeout \u001b[38;5;28;01mas\u001b[39;00m e:\n",
      "\u001b[1;31mNameResolutionError\u001b[0m: <urllib3.connection.HTTPSConnection object at 0x000001B67501F670>: Failed to resolve 'drive.google.com' ([Errno 11001] getaddrinfo failed)",
      "\nThe above exception was the direct cause of the following exception:\n",
      "\u001b[1;31mMaxRetryError\u001b[0m                             Traceback (most recent call last)",
      "File \u001b[1;32mc:\\anaconda\\envs\\object\\lib\\site-packages\\requests\\adapters.py:667\u001b[0m, in \u001b[0;36mHTTPAdapter.send\u001b[1;34m(self, request, stream, timeout, verify, cert, proxies)\u001b[0m\n\u001b[0;32m    666\u001b[0m \u001b[38;5;28;01mtry\u001b[39;00m:\n\u001b[1;32m--> 667\u001b[0m     resp \u001b[38;5;241m=\u001b[39m \u001b[43mconn\u001b[49m\u001b[38;5;241;43m.\u001b[39;49m\u001b[43murlopen\u001b[49m\u001b[43m(\u001b[49m\n\u001b[0;32m    668\u001b[0m \u001b[43m        \u001b[49m\u001b[43mmethod\u001b[49m\u001b[38;5;241;43m=\u001b[39;49m\u001b[43mrequest\u001b[49m\u001b[38;5;241;43m.\u001b[39;49m\u001b[43mmethod\u001b[49m\u001b[43m,\u001b[49m\n\u001b[0;32m    669\u001b[0m \u001b[43m        \u001b[49m\u001b[43murl\u001b[49m\u001b[38;5;241;43m=\u001b[39;49m\u001b[43murl\u001b[49m\u001b[43m,\u001b[49m\n\u001b[0;32m    670\u001b[0m \u001b[43m        \u001b[49m\u001b[43mbody\u001b[49m\u001b[38;5;241;43m=\u001b[39;49m\u001b[43mrequest\u001b[49m\u001b[38;5;241;43m.\u001b[39;49m\u001b[43mbody\u001b[49m\u001b[43m,\u001b[49m\n\u001b[0;32m    671\u001b[0m \u001b[43m        \u001b[49m\u001b[43mheaders\u001b[49m\u001b[38;5;241;43m=\u001b[39;49m\u001b[43mrequest\u001b[49m\u001b[38;5;241;43m.\u001b[39;49m\u001b[43mheaders\u001b[49m\u001b[43m,\u001b[49m\n\u001b[0;32m    672\u001b[0m \u001b[43m        \u001b[49m\u001b[43mredirect\u001b[49m\u001b[38;5;241;43m=\u001b[39;49m\u001b[38;5;28;43;01mFalse\u001b[39;49;00m\u001b[43m,\u001b[49m\n\u001b[0;32m    673\u001b[0m \u001b[43m        \u001b[49m\u001b[43massert_same_host\u001b[49m\u001b[38;5;241;43m=\u001b[39;49m\u001b[38;5;28;43;01mFalse\u001b[39;49;00m\u001b[43m,\u001b[49m\n\u001b[0;32m    674\u001b[0m \u001b[43m        \u001b[49m\u001b[43mpreload_content\u001b[49m\u001b[38;5;241;43m=\u001b[39;49m\u001b[38;5;28;43;01mFalse\u001b[39;49;00m\u001b[43m,\u001b[49m\n\u001b[0;32m    675\u001b[0m \u001b[43m        \u001b[49m\u001b[43mdecode_content\u001b[49m\u001b[38;5;241;43m=\u001b[39;49m\u001b[38;5;28;43;01mFalse\u001b[39;49;00m\u001b[43m,\u001b[49m\n\u001b[0;32m    676\u001b[0m \u001b[43m        \u001b[49m\u001b[43mretries\u001b[49m\u001b[38;5;241;43m=\u001b[39;49m\u001b[38;5;28;43mself\u001b[39;49m\u001b[38;5;241;43m.\u001b[39;49m\u001b[43mmax_retries\u001b[49m\u001b[43m,\u001b[49m\n\u001b[0;32m    677\u001b[0m \u001b[43m        \u001b[49m\u001b[43mtimeout\u001b[49m\u001b[38;5;241;43m=\u001b[39;49m\u001b[43mtimeout\u001b[49m\u001b[43m,\u001b[49m\n\u001b[0;32m    678\u001b[0m \u001b[43m        \u001b[49m\u001b[43mchunked\u001b[49m\u001b[38;5;241;43m=\u001b[39;49m\u001b[43mchunked\u001b[49m\u001b[43m,\u001b[49m\n\u001b[0;32m    679\u001b[0m \u001b[43m    \u001b[49m\u001b[43m)\u001b[49m\n\u001b[0;32m    681\u001b[0m \u001b[38;5;28;01mexcept\u001b[39;00m (ProtocolError, \u001b[38;5;167;01mOSError\u001b[39;00m) \u001b[38;5;28;01mas\u001b[39;00m err:\n",
      "File \u001b[1;32mc:\\anaconda\\envs\\object\\lib\\site-packages\\urllib3\\connectionpool.py:841\u001b[0m, in \u001b[0;36mHTTPConnectionPool.urlopen\u001b[1;34m(self, method, url, body, headers, retries, redirect, assert_same_host, timeout, pool_timeout, release_conn, chunked, body_pos, preload_content, decode_content, **response_kw)\u001b[0m\n\u001b[0;32m    839\u001b[0m     new_e \u001b[38;5;241m=\u001b[39m ProtocolError(\u001b[38;5;124m\"\u001b[39m\u001b[38;5;124mConnection aborted.\u001b[39m\u001b[38;5;124m\"\u001b[39m, new_e)\n\u001b[1;32m--> 841\u001b[0m retries \u001b[38;5;241m=\u001b[39m \u001b[43mretries\u001b[49m\u001b[38;5;241;43m.\u001b[39;49m\u001b[43mincrement\u001b[49m\u001b[43m(\u001b[49m\n\u001b[0;32m    842\u001b[0m \u001b[43m    \u001b[49m\u001b[43mmethod\u001b[49m\u001b[43m,\u001b[49m\u001b[43m \u001b[49m\u001b[43murl\u001b[49m\u001b[43m,\u001b[49m\u001b[43m \u001b[49m\u001b[43merror\u001b[49m\u001b[38;5;241;43m=\u001b[39;49m\u001b[43mnew_e\u001b[49m\u001b[43m,\u001b[49m\u001b[43m \u001b[49m\u001b[43m_pool\u001b[49m\u001b[38;5;241;43m=\u001b[39;49m\u001b[38;5;28;43mself\u001b[39;49m\u001b[43m,\u001b[49m\u001b[43m \u001b[49m\u001b[43m_stacktrace\u001b[49m\u001b[38;5;241;43m=\u001b[39;49m\u001b[43msys\u001b[49m\u001b[38;5;241;43m.\u001b[39;49m\u001b[43mexc_info\u001b[49m\u001b[43m(\u001b[49m\u001b[43m)\u001b[49m\u001b[43m[\u001b[49m\u001b[38;5;241;43m2\u001b[39;49m\u001b[43m]\u001b[49m\n\u001b[0;32m    843\u001b[0m \u001b[43m\u001b[49m\u001b[43m)\u001b[49m\n\u001b[0;32m    844\u001b[0m retries\u001b[38;5;241m.\u001b[39msleep()\n",
      "File \u001b[1;32mc:\\anaconda\\envs\\object\\lib\\site-packages\\urllib3\\util\\retry.py:519\u001b[0m, in \u001b[0;36mRetry.increment\u001b[1;34m(self, method, url, response, error, _pool, _stacktrace)\u001b[0m\n\u001b[0;32m    518\u001b[0m     reason \u001b[38;5;241m=\u001b[39m error \u001b[38;5;129;01mor\u001b[39;00m ResponseError(cause)\n\u001b[1;32m--> 519\u001b[0m     \u001b[38;5;28;01mraise\u001b[39;00m MaxRetryError(_pool, url, reason) \u001b[38;5;28;01mfrom\u001b[39;00m\u001b[38;5;250m \u001b[39m\u001b[38;5;21;01mreason\u001b[39;00m  \u001b[38;5;66;03m# type: ignore[arg-type]\u001b[39;00m\n\u001b[0;32m    521\u001b[0m log\u001b[38;5;241m.\u001b[39mdebug(\u001b[38;5;124m\"\u001b[39m\u001b[38;5;124mIncremented Retry for (url=\u001b[39m\u001b[38;5;124m'\u001b[39m\u001b[38;5;132;01m%s\u001b[39;00m\u001b[38;5;124m'\u001b[39m\u001b[38;5;124m): \u001b[39m\u001b[38;5;132;01m%r\u001b[39;00m\u001b[38;5;124m\"\u001b[39m, url, new_retry)\n",
      "\u001b[1;31mMaxRetryError\u001b[0m: HTTPSConnectionPool(host='drive.google.com', port=443): Max retries exceeded with url: /uc?id=1MMMuun4ioLc046yeqWUuGnTQOSwe_VVK (Caused by NameResolutionError(\"<urllib3.connection.HTTPSConnection object at 0x000001B67501F670>: Failed to resolve 'drive.google.com' ([Errno 11001] getaddrinfo failed)\"))",
      "\nDuring handling of the above exception, another exception occurred:\n",
      "\u001b[1;31mConnectionError\u001b[0m                           Traceback (most recent call last)",
      "Cell \u001b[1;32mIn[17], line 3\u001b[0m\n\u001b[0;32m      1\u001b[0m prefix \u001b[38;5;241m=\u001b[39m \u001b[38;5;124m'\u001b[39m\u001b[38;5;124mhttps://drive.google.com/uc?/export=download&id=\u001b[39m\u001b[38;5;124m'\u001b[39m \n\u001b[1;32m----> 3\u001b[0m \u001b[43mgdown\u001b[49m\u001b[38;5;241;43m.\u001b[39;49m\u001b[43mdownload\u001b[49m\u001b[43m(\u001b[49m\u001b[43murl\u001b[49m\u001b[43m,\u001b[49m\u001b[43m \u001b[49m\u001b[43moutput_path\u001b[49m\u001b[43m,\u001b[49m\u001b[43muse_cookies\u001b[49m\u001b[38;5;241;43m=\u001b[39;49m\u001b[38;5;28;43;01mFalse\u001b[39;49;00m\u001b[43m)\u001b[49m\n",
      "File \u001b[1;32mc:\\anaconda\\envs\\object\\lib\\site-packages\\gdown\\download.py:202\u001b[0m, in \u001b[0;36mdownload\u001b[1;34m(url, output, quiet, proxy, speed, use_cookies, verify, id, fuzzy, resume, format, user_agent, log_messages)\u001b[0m\n\u001b[0;32m    199\u001b[0m     is_gdrive_download_link \u001b[38;5;241m=\u001b[39m \u001b[38;5;28;01mTrue\u001b[39;00m\n\u001b[0;32m    201\u001b[0m \u001b[38;5;28;01mwhile\u001b[39;00m \u001b[38;5;28;01mTrue\u001b[39;00m:\n\u001b[1;32m--> 202\u001b[0m     res \u001b[38;5;241m=\u001b[39m \u001b[43msess\u001b[49m\u001b[38;5;241;43m.\u001b[39;49m\u001b[43mget\u001b[49m\u001b[43m(\u001b[49m\u001b[43murl\u001b[49m\u001b[43m,\u001b[49m\u001b[43m \u001b[49m\u001b[43mstream\u001b[49m\u001b[38;5;241;43m=\u001b[39;49m\u001b[38;5;28;43;01mTrue\u001b[39;49;00m\u001b[43m,\u001b[49m\u001b[43m \u001b[49m\u001b[43mverify\u001b[49m\u001b[38;5;241;43m=\u001b[39;49m\u001b[43mverify\u001b[49m\u001b[43m)\u001b[49m\n\u001b[0;32m    204\u001b[0m     \u001b[38;5;28;01mif\u001b[39;00m \u001b[38;5;129;01mnot\u001b[39;00m (gdrive_file_id \u001b[38;5;129;01mand\u001b[39;00m is_gdrive_download_link):\n\u001b[0;32m    205\u001b[0m         \u001b[38;5;28;01mbreak\u001b[39;00m\n",
      "File \u001b[1;32mc:\\anaconda\\envs\\object\\lib\\site-packages\\requests\\sessions.py:602\u001b[0m, in \u001b[0;36mSession.get\u001b[1;34m(self, url, **kwargs)\u001b[0m\n\u001b[0;32m    594\u001b[0m \u001b[38;5;250m\u001b[39m\u001b[38;5;124mr\u001b[39m\u001b[38;5;124;03m\"\"\"Sends a GET request. Returns :class:`Response` object.\u001b[39;00m\n\u001b[0;32m    595\u001b[0m \n\u001b[0;32m    596\u001b[0m \u001b[38;5;124;03m:param url: URL for the new :class:`Request` object.\u001b[39;00m\n\u001b[0;32m    597\u001b[0m \u001b[38;5;124;03m:param \\*\\*kwargs: Optional arguments that ``request`` takes.\u001b[39;00m\n\u001b[0;32m    598\u001b[0m \u001b[38;5;124;03m:rtype: requests.Response\u001b[39;00m\n\u001b[0;32m    599\u001b[0m \u001b[38;5;124;03m\"\"\"\u001b[39;00m\n\u001b[0;32m    601\u001b[0m kwargs\u001b[38;5;241m.\u001b[39msetdefault(\u001b[38;5;124m\"\u001b[39m\u001b[38;5;124mallow_redirects\u001b[39m\u001b[38;5;124m\"\u001b[39m, \u001b[38;5;28;01mTrue\u001b[39;00m)\n\u001b[1;32m--> 602\u001b[0m \u001b[38;5;28;01mreturn\u001b[39;00m \u001b[38;5;28mself\u001b[39m\u001b[38;5;241m.\u001b[39mrequest(\u001b[38;5;124m\"\u001b[39m\u001b[38;5;124mGET\u001b[39m\u001b[38;5;124m\"\u001b[39m, url, \u001b[38;5;241m*\u001b[39m\u001b[38;5;241m*\u001b[39mkwargs)\n",
      "File \u001b[1;32mc:\\anaconda\\envs\\object\\lib\\site-packages\\requests\\sessions.py:589\u001b[0m, in \u001b[0;36mSession.request\u001b[1;34m(self, method, url, params, data, headers, cookies, files, auth, timeout, allow_redirects, proxies, hooks, stream, verify, cert, json)\u001b[0m\n\u001b[0;32m    584\u001b[0m send_kwargs \u001b[38;5;241m=\u001b[39m {\n\u001b[0;32m    585\u001b[0m     \u001b[38;5;124m\"\u001b[39m\u001b[38;5;124mtimeout\u001b[39m\u001b[38;5;124m\"\u001b[39m: timeout,\n\u001b[0;32m    586\u001b[0m     \u001b[38;5;124m\"\u001b[39m\u001b[38;5;124mallow_redirects\u001b[39m\u001b[38;5;124m\"\u001b[39m: allow_redirects,\n\u001b[0;32m    587\u001b[0m }\n\u001b[0;32m    588\u001b[0m send_kwargs\u001b[38;5;241m.\u001b[39mupdate(settings)\n\u001b[1;32m--> 589\u001b[0m resp \u001b[38;5;241m=\u001b[39m \u001b[38;5;28mself\u001b[39m\u001b[38;5;241m.\u001b[39msend(prep, \u001b[38;5;241m*\u001b[39m\u001b[38;5;241m*\u001b[39msend_kwargs)\n\u001b[0;32m    591\u001b[0m \u001b[38;5;28;01mreturn\u001b[39;00m resp\n",
      "File \u001b[1;32mc:\\anaconda\\envs\\object\\lib\\site-packages\\requests\\sessions.py:703\u001b[0m, in \u001b[0;36mSession.send\u001b[1;34m(self, request, **kwargs)\u001b[0m\n\u001b[0;32m    700\u001b[0m start \u001b[38;5;241m=\u001b[39m preferred_clock()\n\u001b[0;32m    702\u001b[0m \u001b[38;5;66;03m# Send the request\u001b[39;00m\n\u001b[1;32m--> 703\u001b[0m r \u001b[38;5;241m=\u001b[39m adapter\u001b[38;5;241m.\u001b[39msend(request, \u001b[38;5;241m*\u001b[39m\u001b[38;5;241m*\u001b[39mkwargs)\n\u001b[0;32m    705\u001b[0m \u001b[38;5;66;03m# Total elapsed time of the request (approximately)\u001b[39;00m\n\u001b[0;32m    706\u001b[0m elapsed \u001b[38;5;241m=\u001b[39m preferred_clock() \u001b[38;5;241m-\u001b[39m start\n",
      "File \u001b[1;32mc:\\anaconda\\envs\\object\\lib\\site-packages\\requests\\adapters.py:700\u001b[0m, in \u001b[0;36mHTTPAdapter.send\u001b[1;34m(self, request, stream, timeout, verify, cert, proxies)\u001b[0m\n\u001b[0;32m    696\u001b[0m     \u001b[38;5;28;01mif\u001b[39;00m \u001b[38;5;28misinstance\u001b[39m(e\u001b[38;5;241m.\u001b[39mreason, _SSLError):\n\u001b[0;32m    697\u001b[0m         \u001b[38;5;66;03m# This branch is for urllib3 v1.22 and later.\u001b[39;00m\n\u001b[0;32m    698\u001b[0m         \u001b[38;5;28;01mraise\u001b[39;00m SSLError(e, request\u001b[38;5;241m=\u001b[39mrequest)\n\u001b[1;32m--> 700\u001b[0m     \u001b[38;5;28;01mraise\u001b[39;00m \u001b[38;5;167;01mConnectionError\u001b[39;00m(e, request\u001b[38;5;241m=\u001b[39mrequest)\n\u001b[0;32m    702\u001b[0m \u001b[38;5;28;01mexcept\u001b[39;00m ClosedPoolError \u001b[38;5;28;01mas\u001b[39;00m e:\n\u001b[0;32m    703\u001b[0m     \u001b[38;5;28;01mraise\u001b[39;00m \u001b[38;5;167;01mConnectionError\u001b[39;00m(e, request\u001b[38;5;241m=\u001b[39mrequest)\n",
      "\u001b[1;31mConnectionError\u001b[0m: HTTPSConnectionPool(host='drive.google.com', port=443): Max retries exceeded with url: /uc?id=1MMMuun4ioLc046yeqWUuGnTQOSwe_VVK (Caused by NameResolutionError(\"<urllib3.connection.HTTPSConnection object at 0x000001B67501F670>: Failed to resolve 'drive.google.com' ([Errno 11001] getaddrinfo failed)\"))"
     ]
    },
    {
     "ename": "",
     "evalue": "",
     "output_type": "error",
     "traceback": [
      "\u001b[1;31mThe Kernel crashed while executing code in the current cell or a previous cell. \n",
      "\u001b[1;31mPlease review the code in the cell(s) to identify a possible cause of the failure. \n",
      "\u001b[1;31mClick <a href='https://aka.ms/vscodeJupyterKernelCrash'>here</a> for more info. \n",
      "\u001b[1;31mView Jupyter <a href='command:jupyter.viewOutput'>log</a> for further details."
     ]
    }
   ],
   "source": [
    "prefix = 'https://drive.google.com/uc?/export=download&id=' \n",
    "\n",
    "gdown.download(url, output_path,use_cookies=False)"
   ]
  },
  {
   "cell_type": "code",
   "execution_count": null,
   "metadata": {},
   "outputs": [],
   "source": []
  },
  {
   "cell_type": "code",
   "execution_count": null,
   "metadata": {},
   "outputs": [],
   "source": []
  }
 ],
 "metadata": {
  "kernelspec": {
   "display_name": "Python 3",
   "language": "python",
   "name": "python3"
  },
  "language_info": {
   "codemirror_mode": {
    "name": "ipython",
    "version": 3
   },
   "file_extension": ".py",
   "mimetype": "text/x-python",
   "name": "python",
   "nbconvert_exporter": "python",
   "pygments_lexer": "ipython3",
   "version": "3.9.21"
  }
 },
 "nbformat": 4,
 "nbformat_minor": 2
}
